Workbook

Sheet Summary
A1: Healthcare & Lab Locations
A2: Collected October 07, 2026 from each organization's public website
A4: Organization | B4: Locations | C4: States / Regions | D4: Added | E4: Removed | F4: Changed fields | G4: Checks
A5: Jefferson Health | B5: =COUNTA('Jefferson Health'!A:A)-1 -> 447 | C5: =SUMPRODUCT(('Jefferson Health'!F2:F20000<>"")/COUNTIF('Jefferson Health'!F2:F20000,'Jefferson Health'!F2:F20000&"")) -> 4 | D5: =COUNTIFS(Changes!A:A,"Jefferson Health",Changes!B:B,"Added") -> 0 | E5: =COUNTIFS(Changes!A:A,"Jefferson Health",Changes!B:B,"Removed") -> 0 | F5: =COUNTIFS(Changes!A:A,"Jefferson Health",Changes!B:B,"Changed") -> 0 | G5: OK
A6: LVHN | B6: =COUNTA(LVHN!A:A)-1 -> 843 | C6: =SUMPRODUCT((LVHN!I2:I20000<>"")/COUNTIF(LVHN!I2:I20000,LVHN!I2:I20000&"")) -> 2 | D6: =COUNTIFS(Changes!A:A,"LVHN",Changes!B:B,"Added") -> 0 | E6: =COUNTIFS(Changes!A:A,"LVHN",Changes!B:B,"Removed") -> 0 | F6: =COUNTIFS(Changes!A:A,"LVHN",Changes!B:B,"Changed") -> 0 | G6: OK
A7: Quest Diagnostics | B7: =COUNTA('Quest Diagnostics'!A:A)-1 -> 2303 | C7: =SUMPRODUCT(('Quest Diagnostics'!G2:G20000<>"")/COUNTIF('Quest Diagnostics'!G2:G20000,'Quest Diagnostics'!G2:G20000&"")) -> 49 | D7: =COUNTIFS(Changes!A:A,"Quest Diagnostics",Changes!B:B,"Added") -> 1 | E7: =COUNTIFS(Changes!A:A,"Quest Diagnostics",Changes!B:B,"Removed") -> 0 | F7: =COUNTIFS(Changes!A:A,"Quest Diagnostics",Changes!B:B,"Changed") -> 0 | G7: OK
A8: Labcorp | B8: =COUNTA(Labcorp!A:A)-1 -> 2273 | C8: =SUMPRODUCT((Labcorp!F2:F20000<>"")/COUNTIF(Labcorp!F2:F20000,Labcorp!F2:F20000&"")) -> 48 | D8: =COUNTIFS(Changes!A:A,"Labcorp",Changes!B:B,"Added") -> 0 | E8: =COUNTIFS(Changes!A:A,"Labcorp",Changes!B:B,"Removed") -> 0 | F8: =COUNTIFS(Changes!A:A,"Labcorp",Changes!B:B,"Changed") -> 0 | G8: OK
A9: Total | B9: =SUM(B5:B8) -> 5866
A10: Excluded (listed but no data) | B10: =COUNTA(Excluded!A:A)-1 -> 48
A12: Notes
A13: Every row links back to its source page (Location URL). Blank hours mean the website lists none (often "hours vary / please call").
A14: Changes tab: locations added/removed since last month and changed name, address, phone, fax or hours (only when a previous file was supplied).
A15: Quest: Location Type separates Quest patient service centers, joint ventures/affiliates, partner collection sites and international sites.
A16: Labcorp: "Labcorp at Walgreens" = Labcorp service center inside a Walgreens store.
A17: LVHN: Location Types and Services come from the lvhn.org location filters; a location can have several.

Sheet Checks
A1: Source | B1: Check | C1: Result | D1: Status
A2: Jefferson Health | B2: Note | C2: 9 locations are in the search index but their pages return 404 (kept, flagged in Note) | D2: INFO
A3: Jefferson Health | B3: Location count | C3: 447 vs 447 last month (+0.0%) | D3: OK
A4: Jefferson Health | B4: Name filled | C4: 100% (usual ~100%) | D4: OK
A5: Jefferson Health | B5: Street Address filled | C5: 100% (usual ~100%) | D5: OK
A6: Jefferson Health | B6: City filled | C6: 100% (usual ~100%) | D6: OK
A7: Jefferson Health | B7: Phone filled | C7: 98% (usual ~98%) | D7: OK
A8: Jefferson Health | B8: Latitude filled | C8: 100% (usual ~100%) | D8: OK
A9: LVHN | B9: Location count | C9: 843 vs 843 last month (+0.0%) | D9: OK
A10: LVHN | B10: Name filled | C10: 100% (usual ~100%) | D10: OK
A11: LVHN | B11: Street Address filled | C11: 100% (usual ~100%) | D11: OK
A12: LVHN | B12: City filled | C12: 100% (usual ~100%) | D12: OK
... A26: Labcorp | B26: Latitude filled | C26: 100% (usual ~100%) | D26: OK

Sheet Jefferson Health
A1: Name | B1: Location Type | C1: Facility Label | D1: Street Address | E1: City | F1: State | G1: ZIP | H1: County | I1: Latitude | J1: Longitude | K1: Phone | L1: Other Phones | M1: Fax | N1: Email | O1: Open 24 Hours | P1: Monday Hours | Q1: Tuesday Hours | R1: Wednesday Hours | S1: Thursday Hours | T1: Friday Hours | U1: Saturday Hours | V1: Sunday Hours | W1: Hours Footnote | X1: Clinical Specialties | Y1: Conditions | Z1: Treatments | AA1: Wheelchair Accessible | AB1: Public Transportation | AC1: Shuttle Service | AD1: Language Services | AE1: Einstein Location | AF1: Online Scheduling | AG1: Description | AH1: Google Maps Link | AI1: Directions/Parking Page | AJ1: Department Directory | AK1: Location URL | AL1: Last Published | AM1: Note
A2: 3706 Kennett Pike | B2: Practice | D2: 3706 Kennett Pike | E2: Greenville | F2: DE | G2: 19807 | I2: 39.774184 | J2: -75.594847 | K2: 302-477-1991 | M2: 302-477-1994 | O2: No | P2: Closed | Q2: Closed | R2: Closed | S2: Closed | T2: Closed | U2: Closed | V2: Closed | W2: *When traveling to our Wilmington location, enter through the Quillen Building, Suite 1L. | X2: Dermatology; Pigmented Lesion Care; Laser Surgery & Cosmetic Dermatology | AA2: No | AB2: No | AE2: No | AG2: Our Kennett Pike practice offers dermatology and cosmetic services. | AH2: https://www.google.com/maps/place/3706+Kennett+Pike,+Greenville,+DE+19807/@39.7741841,-75.5948468,17z/data=!3m1!4b1!4m6!3m5!1s0x89c6fc4ae6474bb3:0x457d13beacb1bc61!8m2!3d39.7741841!4d-75.5948468!16s%2Fg%2F11c1yj8619 | AK2: https://www.jeffersonhealth.org/locations/3706-kennett-pike | AL2: 2026-01-24
A3: Jefferson Gastroenterology & Hepatology Associates | B3: Practice | D3: 4735 Ogletown-Stanton Road, Suite 3301 | E3: Newark | F3: DE | G3: 19713 | I3: 39.670937 | J3: -75.708073 | K3: 215-955-8900 | O3: No | X3: Liver Transplant; Viral Hepatitis Care; Gastroenterology & Hepatology; Transplant Institute; Fatty Liver Care; Liver Tumor; Barrett's Esophagus Care | AA3: No | AB3: No | AE3: No | AF3: No | AG3: Jefferson Gastroenterology & Hepatology Associates offers its patients expert care. | AH3: https://www.google.com/maps/place/4735+Ogletown+Stanton+Rd,+Newark,+DE+19713/data=!4m2!3m1!1s0x89c700e14988170f:0xb87ad107bdbd8d9e?sa=X&ved=2ahUKEwily7qxsvv3AhWajIkEHR9LAm0Q8gF6BAgCEAE | AK3: https://www.jeffersonhealth.org/locations/4735-ogletown-stanton-road | AL3: 2026-01-24
A4: 3521 Silverside Road | B4: Practice | D4: 3521 Silverside Road, Suite 1L | E4: Wilmington | F4: DE | G4: 19810 | I4: 39.810868 | J4: -75.547463 | K4: 1-800-533-3669 | O4: No | P4: Closed | Q4: Closed | R4: Closed | S4: Closed | T4: Closed | U4: Closed | V4: Closed | W4: *When traveling to our Wilmington location, enter through the Quillen Building, Suite 1L. | AA4: No | AB4: No | AE4: No | AF4: No | AG4: Our Silverside Road practice offers dermatology and cosmetic services. | AH4: http://maps.google.com/?q=3521+Silverside+Road%2c+Wilmington%2c+DE+19810 | AK4: https://www.jeffersonhealth.org/locations/3521-silverside-road | AL4: 2026-01-24
A5: Nemours Children’s Health – Wilmington | B5: Practice | D5: 1600 Rockland Road | E5: Wilmington | F5: DE | G5: 19899 | I5: 39.778655 | J5: -75.558516 | K5: 1-800-416-4441 | O5: No | X5: Respiratory & Pulmonary Medicine; Gynecology; Surgery; Pediatric Neurosurgery; Pediatric Otolaryngology; Pediatric Allergy & Immunology; Pediatric Urology; Pediatric Rehabilitation Medicine; Otolaryngology; Ophthalmology; Pediatric General Surgery; Orthopedics; Pediatric Dermatology; Pediatric Neurology; Pediatric & Adolescent Gynecology; Pediatric Cardiology; Pediatrics; Pediatric Gastroenterology; Pediatric Endocrinology; General Surgery | AA5: Yes | AB5: Yes | AC5: No | AD5: No | AE5: No | AF5: No | AG5: Nemours Children's Health in Wilmington, DE, world-class pediatric care, close to home. | AH5: http://maps.google.com/?q=1600+Rockland+Road%2c+Wilmington%2c+DE+19899 | AK5: https://www.jeffersonhealth.org/locations/nemours-childrens-health | AL5: 2026-01-24
A6: Cherry Hill MOB General Surgery & Specialty Care | B6: Practice | D6: 2211 Chapel Avenue West | E6: Cherry Hill | F6: NJ | G6: 08002 | I6: 39.928668 | J6: -75.015803 | K6: 1-800-JEFF-NOW | O6: No | P6: 08:00 am - 04:30 pm | Q6: 08:00 am - 04:30 pm | R6: 08:00 am - 04:30 pm | S6: 08:00 am - 04:30 pm | T6: 08:00 am - 04:30 pm | U6: Closed | V6: Closed | X6: General Surgery; Breast Surgery; Bariatric Surgery Program; Medical & Surgical Weight Loss; Sleep Medicine; Colorectal Surgery; Breast Care; Comprehensive Weight Management; Obstetrics & Gynecology; Obstetrics; Obstetrics & Maternity Care; Gynecology; Vascular & Endovascular Surgery | AA6: Yes | AB6: Yes | AC6: No | AD6: Yes | AE6: No | AF6: No | AG6: General, bariatric, vascular, cardiothoracic and breast surgery specialists in Cherry Hill, NJ. | AH6: https://www.google.com/maps/place/Jefferson+Health+Cherry+Hill+General+Surgery+%26+Specialty+Care/@39.9308071,-75.0422175,15z/data=!4m9!1m2!2m1!1scherry+hill+MOB+specialty+care!3m5!1s0x89c6cb2f6c389ccd:0x86153d7440a00fae!8m2!3d39.927916!4d-75.015734!15sCh5jaGVycnkgaGlsbCBNT0Igc3BlY2lhbHR5IGNhcmWSAQ9zdXJnaWNhbF9jZW50ZXI | AJ6: https://www.jeffersonhealth.org/locations/cherry-hill-mob-general-surgery-specialty-care/department-directory | AK6: https://www.jeffersonhealth.org/locations/cherry-hill-mob-general-surgery-specialty-care | AL6: 2026-07-28
A7: Cherry Hill Primary & Specialty Care | B7: Practice | D7: 457 Haddonfield Road, Suite 110 | E7: Cherry Hill | F7: NJ | G7: 08002 | I7: 39.934396 | J7: -75.02991 | K7: 844-542-2273 | M7: 856-406-4570 | O7: No | P7: 07:30 am - 07:00 pm | Q7: 07:00 am - 05:00 pm | R7: 08:00 am - 06:00 pm | S7: 08:00 am - 07:00 pm | T7: 07:00 am - 04:00 pm | U7: Closed | V7: Closed | X7: Lung Cancer, Screening, and Nodules; Primary Care; Neuroscience; Sleep Medicine; Respiratory & Pulmonary Medicine; Family & Community Medicine; Sports Medicine; Rheumatology; Vascular & Endovascular Surgery | Y7: Lung Nodule | AA7: No | AB7: No | AC7: No | AD7: No | AE7: No | AF7: No | AG7: Jefferson Health's Cherry Hill Primary & Specialty Care offers a wide variety of services including nutrition, pain management and sleep medicine. | AH7: https://www.google.com/maps/place/Jefferson+Health+Cherry+Hill+Primary+%26+Specialty+Care/@39.9343962,-75.0299099,15.75z/data=!4m21!1m15!4m14!1m6!1m2!1s0x89c13c58e7603965:0x953d469e0f75a68c!2sTabernacle,+New+Jersey!2m2!1d-74.7107048!2d39.8433853!1m6!1m2!1s0x89c6cbb150654aab:0xa6878cabff976f9f!2sJefferson+Health+Cherry+Hill+Primary+%26+Specialty+Care,+457+Haddonfield+Rd+%23110,+Cherry+Hill,+NJ+08002!2m2!1d-75.0313455!2d39.9364238!3m4!1s0x89c6cbb150654aab:0xa6878cabff976f9f!8m2!3d39.9364238!4d-75.0313455 | AK7: https://www.jeffersonhealth.org/locations/cherry-hill-primary-specialty-care | AL7: 2026-08-26
A8: Fibroid Center - 2201 Chapel Ave West | B8: Practice | D8: 2201 Chapel Ave West | E8: Cherry Hill | F8: NJ | G8: 08002 | I8: 39.931173 | J8: -75.026067 | K8: 856-922-4347 | O8: No | P8: 07:30 am - 05:00 pm | Q8: Closed | R8: 07:30 am - 05:00 pm | S8: 07:30 am - 05:00 pm | T8: Closed | U8: Closed | V8: Closed | X8: Fibroid Care; Interventional Radiology | Z8: Uterine Fibroid Embolization | AA8: No | AB8: No | AC8: No | AD8: No | AE8: No | AF8: No | AH8: https://www.google.com/maps/place/Jefferson+Cherry+Hill+Hospital/@39.9279172,-75.0184571,17z/data=!3m1!4b1!4m5!3m4!1s0x89c6cba7982122fb:0x10ce11b5706b1486!8m2!3d39.9279172!4d-75.0162684 | AK8: https://www.jeffersonhealth.org/locations/fibroid-center-2201-chapel-ave-west | AL8: 2026-01-24
A9: Gastroenterology Cherry Hill | B9: Practice | D9: 2211 Chapel Avenue West, Suite 401 | E9: Cherry Hill | F9: NJ | G9: 08002 | I9: 39.927987 | J9: -75.015708 | K9: 215-955-8900 | M9: 856-662-2804 | O9: No | P9: 08:00 am - 04:30 pm | Q9: 08:00 am - 04:30 pm | R9: 08:00 am - 04:30 pm | S9: 08:00 am - 04:30 pm | T9: 08:00 am - 04:30 pm | U9: Closed | V9: Closed | W9: *Temporarily expanded office hours subject to change. | X9: Gastroenterology & Hepatology; Gastroesophageal Care | AA9: No | AB9: No | AC9: No | AD9: No | AE9: No | AF9: Yes | AG9: Gastroenterology services at Cherry Hill, NJ. | AH9: https://www.google.com/maps/place/Jefferson+Health+Cherry+Hill+Gastroenterology/@39.9279868,-75.0157083,15z/data=!4m2!3m1!1s0x0:0xbf023d20b5ddb2e8?sa=X&ved=2ahUKEwj4rLqG6dbzAhWsq3IEHVXqDoYQ_BJ6BAhuEAU | AK9: https://www.jeffersonhealth.org/locations/gastroenterology-cherry-hill | AL9: 2026-01-24
A10: Jefferson Cherry Hill Hospital | B10: Hospital; Imaging | C10: Hospital | D10: 2201 Chapel Ave West | E10: Cherry Hill | F10: NJ | G10: 08002 | I10: 39.928908 | J10: -75.01664 | K10: 856-488-6500 | L10: Emergency Department: 856-488-6816 | O10: Yes | P10: Closed | Q10: Closed | R10: Closed | S10: Closed | T10: Closed | U10: Closed | V10: 09:00 am - 05:00 pm | W10: Emergency Department open 24 hours daily. Please use visiting hours link for department specific hours. | X10: Balance & Hearing; Psychiatry & Human Behavior; Imaging & Radiology; Nutrition; Orthopedics; General Surgery; Sleep Medicine; Stroke; Emergency Medicine; Diabetes; Surgery; Wound Care & Hyperbaric Oxygen Therapy; Minimally Invasive & Robotic Surgery; Interventional Radiology; Fibroid Care; Hospital Medicine; Lower Extremity Orthopedics; Gastroenterology & Hepatology; Outpatient Imaging | AA10: Yes | AB10: Yes | AC10: Yes | AD10: Yes | AE10: No | AF10: No | AG10: Receive the best all-around care in the region in our recently completed $250 million hospital transformation including a new inpatient tower with private rooms. | AH10: https://www.google.com/maps/place/Jefferson+Cherry+Hill+Hospital/@39.9279172,-75.0184571,17z/data=!3m1!4b1!4m5!3m4!1s0x89c6cba7982122fb:0x10ce11b5706b1486!8m2!3d39.9279172!4d-75.0162684 | AI10: https://www.jeffersonhealth.org/locations/cherry-hill-hospital/getting-here | AJ10: https://www.jeffersonhealth.org/locations/cherry-hill-hospital/department-directory | AK10: https://www.jeffersonhealth.org/locations/cherry-hill-hospital | AL10: 2026-08-28
A11: Jefferson Moss-Magee Rehabilitation – Cherry Hill | B11: Outpatient Rehabilitation | D11: 2211 Chapel Avenue | E11: Cherry Hill | F11: NJ | G11: 08002 | I11: 39.928226 | J11: -75.015977 | K11: 856-922-5090 | M11: 856-922-5096 | O11: No | W11: Open Monday through Friday, evening hours are available | X11: Rehabilitation Medicine; Outpatient Rehabilitation; Spinal Cord Injury Rehabilitation; Physical Therapy; Stroke Rehabilitation; Orthopedic Injury Rehabilitation; Speech Therapy Program; Brain Injury Rehabilitation | Y11: Lymphedema; Pelvic Pain; Concussion & Head Injuries | Z11: Occupational Therapy; Physical Therapy; Pelvic Floor Therapy; Speech Therapy | AA11: No | AB11: Yes | AC11: No | AD11: No | AE11: No | AF11: No | AG11: Jefferson Moss-Magee Rehabilitation – Cherry Hill offers a menu of services to assist an individual's recovery of functional ability regardless of the severity of the initial injury. | AH11: https://www.google.com/maps/place/2211+Chapel+Ave,+Cherry+Hill,+NJ+08002/@39.9287739,-75.0178616,17z/data=!3m1!4b1!4m5!3m4!1s0x89c6cba7c1ea5443:0x7fc8f435933835e3!8m2!3d39.9287698!4d-75.0156729 | AK11: https://www.jeffersonhealth.org/locations/moss-magee-rehabilitation-cherry-hill | AL11: 2026-07-07
A12: Jefferson Radiation Oncology – Cherry Hill | B12: Practice | D12: 2211 Chapel Ave West | E12: Cherry Hill | F12: NJ | G12: 08002 | I12: 39.928668 | J12: -75.015803 | K12: 856-922-4800 | M12: 856-922-4801 | O12: No | P12: 07:30 am - 04:00 pm | Q12: 07:30 am - 04:00 pm | R12: 07:30 am - 04:00 pm | S12: 07:30 am - 04:00 pm | T12: 07:30 am - 04:00 pm | U12: Closed | V12: Closed | X12: Radiation Oncology | AA12: Yes | AB12: Yes | AC12: No | AD12: Yes | AE12: No | AF12: No | AG12: Radiation oncology services at the Sidney Kimmel Comprehensive Cancer Center - Cherry Hill. | AK12: https://www.jeffersonhealth.org/locations/radiation-oncology-cherry-hill | AL12: 2026-01-24
A13: Jefferson Surgery Center - Cherry Hill | B13: Surgical Center | D13: 2211 Chapel Ave West | E13: Cherry Hill | F13: NJ | G13: 08002 | I13: 39.92805 | J13: -75.017723 | K13: 856-295-9041 | O13: No | P13: 06:00 am - 04:30 pm | Q13: 06:00 am - 04:30 pm | R13: 06:00 am - 04:30 pm | S13: 06:00 am - 04:30 pm | T13: 06:00 am - 04:30 pm | U13: Closed | V13: Closed | X13: General Surgery; Surgery; Gastroenterology & Hepatology | AA13: No | AB13: No | AC13: No | AD13: No | AE13: No | AF13: No | AG13: The Surgery team at Jefferson Surgery Center - Cherry Hill offers expertise you can trust throughout the greater South Jersey area. | AH13: https://www.google.com/maps/place/2211+Chapel+Ave+W+Ste+200,+Cherry+Hill,+NJ+08002/@39.9281152,-75.0168332,18z/data=!4m6!3m5!1s0x89c6cba7bdc5783b:0x959e4b94ad83bac7!8m2!3d39.9282252!4d-75.0159773!16s%2Fg%2F11tnj6y_t4?entry=ttu | AK13: https://www.jeffersonhealth.org/locations/surgery-center-cherry-hill | AL13: 2026-01-24
A14: Jefferson Urology – Cherry Hill | B14: Practice | D14: 63 Kresson Road, Suite 103 | E14: Cherry Hill | F14: NJ | G14: 08034 | I14: 39.89448 | J14: -75.01984 | K14: 844-542-2273 | M14: 856-667-2428 | O14: No | P14: 08:00 am - 04:30 pm | Q14: 08:00 am - 04:30 pm | R14: 08:00 am - 04:30 pm | S14: 08:00 am - 04:30 pm | T14: 08:00 am - 04:30 pm | U14: Closed | V14: Closed | X14: Urology | AA14: No | AB14: No | AC14: No | AD14: No | AE14: No | AF14: No | AG14: The urologist specialist team at Jefferson Urology – Cherry Hill collaborates with other specialists across programs and centers dedicated to your unique health needs – from cancer to men's health to LGBTQIA+ care – to provide you with complete urological care, close to home. | AH14: https://www.google.com/maps/place/63+Kresson+Rd,+Cherry+Hill+Township,+NJ+08034/@39.8945748,-75.0201016,17z/data=!3m1!4b1!4m6!3m5!1s0x89c6cc7c07d8a317:0xee6a9da1ab0dff8e!8m2!3d39.8945748!4d-75.0201016!16s%2Fg%2F11c3q39h3n?entry=ttu&g_ep=EgoyMDI1MTAyNy4wIKXMDSoASAFQAw%3D%3D | AK14: https://www.jeffersonhealth.org/locations/urology-cherry-hill | AL14: 2026-09-21
A15: Jefferson–Solis Mammography – Cherry Hill | B15: Imaging | C15: A department of Jefferson Cherry Hill Hospital | D15: 2201 Chapel Ave West | E15: Cherry Hill | F15: NJ | G15: 08002 | I15: 39.928736 | J15: -75.016597 | K15: 856-214-0693 | O15: No | P15: 06:30 am - 05:00 pm | Q15: 06:30 am - 05:00 pm | R15: 06:30 am - 05:00 pm | S15: 06:30 am - 05:00 pm | T15: 06:30 am - 05:00 pm | U15: 08:00 am - 12:00 pm | V15: Closed | X15: Breast Care; Breast Imaging; Women's Imaging; Imaging & Radiology | Z15: Abnormal Mammogram; Mammogram; Bone Densitometry; Breast Ultrasound; Breast Biopsy | AA15: Yes | AB15: Yes | AC15: Yes | AD15: Yes | AE15: No | AF15: No | AG15: Jefferson Health has partnered with Solis Mammography, the nation’s leader in screening and diagnostic mammography, to serve as an on-site provider of comprehensive breast imaging services at Jefferson locations throughout the greater Philadelphia and South Jersey area. | AH15: https://www.google.com/maps/place/Jefferson+Cherry+Hill+Hospital/@39.9287357,-75.0165973,17z/data=!3m1!4b1!4m6!3m5!1s0x89c6cba7982122fb:0x10ce11b5706b1486!8m2!3d39.9287357!4d-75.0165973!16s%2Fg%2F1tfn3pyq?entry=ttu | AI15: https://www.jeffersonhealth.org/locations/cherry-hill-hospital/getting-here | AK15: https://www.jeffersonhealth.org/locations/solis-mammography-cherry-hill | AL15: 2026-01-24
A16: Otolaryngology - Head & Neck Surgery at Cherry Hill | B16: Practice | D16: 2211 Chapel Avenue West, Suite 403 | E16: Cherry Hill | F16: NJ | G16: 08002 | I16: 39.928225 | J16: -75.015977 | K16: 856-922-5030 | M16: 856-662-2545 | O16: No | P16: 08:00 am - 04:30 pm | Q16: 08:00 am - 04:30 pm | R16: 08:00 am - 04:30 pm | S16: 08:00 am - 04:30 pm | T16: 08:00 am - 04:30 pm | U16: Closed | V16: Closed | X16: Otolaryngology; Head & Neck Surgery | AA16: No | AB16: No | AC16: No | AD16: No | AE16: No | AF16: Yes | AG16: Otolaryngology, head and neck surgery in Cherry Hill, NJ. | AH16: https://www.google.com/maps/place/2211+Chapel+Ave+W,+Cherry+Hill,+NJ+08002/@39.9282244,-75.0181662,17z/data=!3m1!4b1!4m5!3m4!1s0x89c6cba7c0924529:0x2552c2dddc9ce0fc!8m2!3d39.9282244!4d-75.0159775 | AK16: https://www.jeffersonhealth.org/locations/otolaryngology-head-neck-surgery-cherry-hill | AL16: 2026-01-24
A17: Delran Primary Care | B17: Practice | D17: 8008 Route 130 | E17: Delran | F17: NJ | G17: 08075 | I17: 40.02366 | J17: -74.937555 | K17: 844-542-2273 | M17: 856-764-1840 | O17: No | P17: 07:00 am - 07:00 pm | Q17: 07:00 am - 07:00 pm | R17: 08:00 am - 03:30 pm | S17: 07:30 am - 03:30 pm | T17: 07:00 am - 03:00 pm | U17: Closed | V17: Closed | W17: *Temporarily expanded office hours subject to change. | X17: Primary Care | AA17: No | AB17: No | AC17: No | AD17: No | AE17: No | AF17: Yes | AG17: Primary care services in Delran, NJ. | AH17: https://www.google.com/maps/place/Jefferson+Health+Delran+Primary+Care/@40.0236604,-74.9397437,17z/data=!3m1!4b1!4m5!3m4!1s0x89c14bc6221e5021:0x4f8058824b1ba562!8m2!3d40.0236604!4d-74.937555 | AK17: https://www.jeffersonhealth.org/locations/delran-primary-care | AL17: 2026-01-24
A18: 2500 English Creek Avenue | B18: Outpatient Medical Center | D18: 2500 English Creek Avenue | E18: Egg Harbor Township | F18: NJ | G18: 08234 | I18: 39.348042 | J18: -74.663464 | K18: 800-533-3669 | O18: No | X18: Liver Transplant; Transplant Institute; Kidney Transplant; Nephrology; Viral Hepatitis Care; Gastroenterology & Hepatology; Rothman Institute; Fatty Liver Care; Liver Tumor; Orthopedics | AA18: No | AB18: Yes | AC18: No | AD18: No | AE18: No | AF18: No | AG18: Digestive Health, Orthopaedics and Organ transplants in Egg Harbor Township, NJ. | AH18: https://www.google.com/maps/search/2500+English+Creek+Avenue,+Atlantic+Care+Complex,+Egg+Harbor+Township,+NJ+08234/@39.4348176,-74.607614,17z/data=!3m1!4b1 | AJ18: https://www.jeffersonhealth.org/locations/2500-english-creek-avenue/department-directory | AK18: https://www.jeffersonhealth.org/locations/2500-english-creek-avenue | AL18: 2026-03-25
A19: Jefferson Foot & Ankle – Haddonfield | B19: Practice | D19: 308 N. Haddon Avenue | E19: Haddonfield | F19: NJ | G19: 08033 | I19: 39.90234 | J19: -75.03923 | K19: 856-414-8799 | M19: 215-521-7139 | O19: No | P19: Closed | Q19: Closed | R19: 08:00 am - 04:00 pm | S19: 08:00 am - 03:00 pm | T19: 08:00 am - 03:00 pm | U19: Closed | V19: Closed | W19: *Wednesday, 1st and 4th of the month only* | X19: Foot & Ankle Orthopedic Surgery; Foot Orthopedic Surgery; Lower Extremity Orthopedics | Y19: Foot Problems & Pain; Arthritis; Osteoarthritis | AA19: No | AB19: No | AC19: No | AD19: No | AE19: No | AF19: No | AG19: Jefferson Foot & Ankle – Haddonfield offers lower extremity orthopedics services to its patients. | AH19: https://www.google.com/maps/place/Jefferson+Foot+%26+Ankle+Surgery+-+Haddonfield/@39.9024466,-75.0391575,15z/data=!4m2!3m1!1s0x0:0xada2306aea499bca?sa=X&ved=1t:2428&hl=en&ictx=111 | AK19: https://www.jeffersonhealth.org/locations/foot-ankle-haddonfield | AL19: 2026-05-04
A20: Jefferson Pride Care | B20: Practice | D20: 15 E. Redman Avenue | E20: Haddonfield | F20: NJ | G20: 08033 | I20: 39.89969 | J20: -75.03466 | K20: 856-414-8758 | M20: 856-429-0891 | O20: No | P20: 08:00 am - 07:40 pm | Q20: 08:00 am - 05:00 pm | R20: 08:00 am - 07:00 pm | S20: 08:00 am - 06:00 pm | T20: 08:00 am - 04:30 pm | U20: Closed | V20: Closed | X20: Pride Care; Family & Community Medicine; Ryan White Program; Breast Care; Primary Care; Obstetrics & Gynecology; Midwifery; Sleep Medicine; Infectious Diseases; Breast Surgery | AA20: Yes | AB20: Yes | AC20: No | AD20: No | AE20: No | AF20: No | AG20: Primary care and specialty services for LGBTQIA+ patients at Jefferson Pride Care. | AH20: https://www.google.com/maps/dir//Jefferson+Pride+Care/data=!4m6!4m5!1m1!4e2!1m2!1m1!1s0x89c6cd5cf24cb433:0x987f00bb4d17feda?sa=X&ved=1t:3061&hl=en&ictx=111 | AJ20: https://www.jeffersonhealth.org/locations/pride-care/department-directory | AK20: https://www.jeffersonhealth.org/locations/pride-care | AL20: 2026-09-30
A21: Jefferson Primary & Specialty Care – Haddonfield | B21: Practice | D21: 80 Tanner Street | E21: Haddonfield | F21: NJ | G21: 08033 | I21: 39.900329 | J21: -75.039516 | K21: 856-922-9700 | M21: 856-428-6334 | O21: No | P21: 08:00 am - 08:00 pm | Q21: 07:40 am - 07:20 pm | R21: 08:00 am - 08:00 pm | S21: 08:00 am - 08:00 pm | T21: 08:00 am - 04:00 pm | U21: Closed | V21: Closed | X21: Primary Care; Family & Community Medicine | AA21: No | AB21: No | AC21: No | AD21: No | AE21: No | AF21: Yes | AG21: Jefferson Primary & Specialty Care – Haddonfield (formerly Redman Avenue Primary Care) offers primary care & family medicine services in Haddonfield, NJ. | AH21: https://www.google.com/maps/dir//Redman+Avenue+Primary+Care/data=!4m6!4m5!1m1!4e2!1m2!1m1!1s0x89c6cd448e6fe2d7:0x334b1218a755116a?sa=X&ved=1t:3061&hl=en&ictx=111 | AK21: https://www.jeffersonhealth.org/locations/primary-specialty-haddonfield | AL21: 2026-08-31
A22: Jefferson Outpatient Imaging – Marlton | B22: Imaging | D22: 999 Route 73 North | E22: Marlton | F22: NJ | G22: 08053 | I22: 39.907864 | J22: -74.942703 | K22: 215-503-4900 | M22: 215-521-6432 | O22: No | X22: Outpatient Imaging; Imaging & Radiology | AA22: No | AB22: No | AC22: No | AD22: No | AE22: No | AF22: No | AG22: The Jefferson Outpatient Imaging – Marlton location offers outpatient imaging services to its patients. | AH22: https://maps.app.goo.gl/JyWYfuDGsCwp7zqEA | AK22: https://www.jeffersonhealth.org/locations/999-route-73 | AL22: 2026-02-02
A23: Marlton Primary & Specialty Care | B23: Practice | D23: 73 North Maple Avenue, Suite A, B, C | E23: Marlton | F23: NJ | G23: 08053 | I23: 39.907203 | J23: -74.921992 | K23: 844-542-2273 | M23: 856-596-4043 | O23: No | P23: 07:40 am - 07:00 pm | Q23: 07:20 am - 07:00 pm | R23: 07:20 am - 05:40 pm | S23: 07:40 am - 07:00 pm | T23: 07:40 am - 03:40 pm | U23: Closed | V23: Closed | W23: *Temporarily expanded office hours subject to change. | X23: Primary Care; Neuroscience; Family & Community Medicine; Endocrinology, Diabetes, & Metabolic Diseases; Comprehensive Weight Management; Rheumatology; Colorectal Surgery; Nutrition; Neurology | AA23: No | AB23: No | AC23: No | AD23: No | AE23: No | AF23: No | AG23: Primary & specialty care services in Marlton, NJ. | AH23: https://www.google.com/maps/place/Jefferson+Health+Marlton+Primary+%26+Specialty+Care/@39.9072033,-74.9241808,17z/data=!3m1!4b1!4m5!3m4!1s0x89c1348830201adb:0xf8ccde9caeff6d31!8m2!3d39.9072033!4d-74.9220035 | AJ23: https://www.jeffersonhealth.org/locations/marlton-primary-specialty-care/department-directory | AK23: https://www.jeffersonhealth.org/locations/marlton-primary-specialty-care | AL23: 2026-09-23
A24: 445 Hurffville Crosskeys Road | B24: Practice | D24: 445 Hurffville-Crosskeys Road | E24: Sewell | F24: NJ | G24: 08080 | I24: 39.735518 | J24: -75.137406 | K24: 1-800-JEFF-NOW | M24: 856-256-7595 | O24: No | X24: Spine Care; Neuroscience; Neurosurgery; Stroke Care | AA24: No | AB24: Yes | AC24: No | AD24: No | AE24: No | AF24: No | AG24: Neurosurgery, Spine Program, and Comprehensive Stroke Center in Sewell, NJ. | AH24: https://www.google.com/maps/place/Parking+lot,+445+Hurffville+-+Cross+Keys+Rd,+Sewell,+NJ+08080/@39.7357444,-75.0677309,17z/data=!3m1!4b1!4m5!3m4!1s0x89c6d6af5a66d70b:0x503a9727938554f7!8m2!3d39.7357444!4d-75.0677309 | AK24: https://www.jeffersonhealth.org/locations/445-hurffville-crosskeys-road | AL24: 2026-01-24
A25: Fibroid Center - 555 Egg Harbor Road | B25: Practice | D25: 555 Egg Harbor Road | E25: Sewell | F25: NJ | G25: 08080 | I25: 39.735838 | J25: -75.065937 | K25: 856-582-2555 | O25: No | P25: 07:30 am - 05:00 pm | Q25: 07:30 am - 05:00 pm | R25: 07:30 am - 05:00 pm | S25: 07:30 am - 05:00 pm | T25: 07:30 am - 05:00 pm | U25: Closed | V25: Closed | X25: Fibroid Care; Interventional Radiology | Z25: Uterine Fibroid Embolization | AA25: No | AB25: No | AC25: No | AD25: No | AE25: No | AF25: No | AH25: https://goo.gl/maps/ZCSS28x6dng1vUNy5 | AK25: https://www.jeffersonhealth.org/locations/fibroid-center-555-egg-harbor-road | AL25: 2026-01-24
A26: Gynecologic Oncology - 900 Medical Center Drive | B26: Practice | D26: 900 Medical Center Drive, Suite 205 | E26: Sewell | F26: NJ | G26: 08080 | I26: 39.73857 | J26: -75.064683 | K26: 856-557-5400 | M26: 856-553-6713 | O26: No | P26: 08:00 am - 04:30 pm | Q26: 08:00 am - 04:30 pm | R26: 08:00 am - 04:30 pm | S26: 08:00 am - 04:30 pm | T26: 08:00 am - 04:30 pm | U26: Closed | V26: Closed | W26: *Temporarily expanded office hours subject to change. | X26: Gynecologic Oncology | AA26: Yes | AB26: Yes | AC26: Yes | AD26: Yes | AE26: No | AF26: No | AG26: Gynecologic oncology services at Sidney Kimmel Comprehensive Cancer Center - Washington Township. | AH26: https://www.google.com/maps/place/Jefferson+Health+Washington+Township+Gynecologic+Oncology/@39.7384935,-75.0668592,17z/data=!3m1!4b1!4m5!3m4!1s0x89c6d73f04855df1:0x54b13acb9d075f3b!8m2!3d39.7384004!4d-75.0648703 | AK26: https://www.jeffersonhealth.org/locations/gynecologic-oncology-900-medical-center-drive | AL26: 2026-01-24
A27: Jefferson Breast Surgery – Washington Township | B27: Practice | D27: 900 Medical Center Drive, Suite 201 | E27: Sewell | F27: NJ | G27: 08080 | I27: 39.738613 | J27: -75.064674 | K27: 856-218-2100 | M27: 856-218-2101 | O27: No | P27: 08:30 am - 05:00 pm | Q27: 08:30 am - 05:00 pm | R27: 08:30 am - 05:00 pm | S27: 08:30 am - 05:00 pm | T27: 08:30 am - 05:00 pm | U27: Closed | V27: Closed | X27: Breast Surgery; Breast Care; Breast Medical Oncology | Z27: Top Surgery | AA27: Yes | AB27: Yes | AC27: Yes | AD27: Yes | AE27: No | AF27: No | AG27: Jefferson Breast Surgery at Sidney Kimmel Comprehensive Cancer Center – Washington Township offers comprehensive breast care to its patients. | AH27: https://www.google.com/maps/place/Jefferson+Health+Comprehensive+Breast+Center/@39.7386168,-75.0668625,17z/data=!3m1!4b1!4m5!3m4!1s0x89c6d789172fa219:0x5abf66759f91cc70!8m2!3d39.7384896!4d-75.064938 | AK27: https://www.jeffersonhealth.org/locations/comprehensive-breast-center-900-medical-center-drive | AL27: 2026-04-15
A28: Jefferson Outpatient Imaging – Washington Township | B28: Imaging | D28: 243 Hurffville Crosskeys Road | E28: Sewell | F28: NJ | G28: 08080 | I28: 39.722378 | J28: -75.045057 | K28: 215-503-4900 | O28: No | X28: Outpatient Imaging; Women's Imaging; Ultrasound; Imaging & Radiology | Z28: Ultrasound; Abnormal Mammogram; Mammogram | AA28: No | AB28: No | AC28: No | AD28: No | AE28: No | AF28: No | AG28: Jefferson Outpatient Imaging – Washington Township offers outpatient imaging services to its patients. | AH28: https://goo.gl/maps/a2cybUkZdoHbdPNBA | AK28: https://www.jeffersonhealth.org/locations/243-hurffville-crosskeys-road | AL28: 2026-01-24
A29: Jefferson Primary & Specialty Care – Fish Pond Road | B29: Practice | D29: 354 Hurffville - Cross Keys Road | E29: Sewell | F29: NJ | G29: 08080 | I29: 39.730275 | J29: -75.058859 | K29: 1-800-JEFF-NOW | O29: No | P29: 07:30 am - 05:00 pm | Q29: 07:30 am - 05:00 pm | R29: 07:30 am - 05:00 pm | S29: 07:30 am - 05:00 pm | T29: 07:30 am - 05:00 pm | U29: Closed | V29: Closed | X29: Primary Care; Nutrition; Infectious Diseases; Family & Community Medicine; Endocrinology, Diabetes, & Metabolic Diseases; Urology; Behavioral Medicine; Gastroenterology & Hepatology; General Surgery; Pain Management; Rheumatology; Vascular Surgery; Colorectal Surgery; Allergy & Immunology; Otolaryngology; Comprehensive Weight Management; Ryan White Program; Bariatric Surgery; Bariatric Surgery Program | AA29: Yes | AB29: Yes | AC29: No | AD29: No | AE29: No | AF29: No | AG29: Jefferson Primary & Specialty Care – Fish Pond Road offers both primary and specialty care services in Washington Township, NJ. | AH29: https://www.google.com/maps/place/Jefferson+Health+Fish+Pond+Primary+%26+Specialty+Care/@39.7293674,-75.0589016,15z/data=!4m2!3m1!1s0x0:0x68d496400eda2d0e?sa=X&ved=2ahUKEwjg9pXYkt7zAhUrU98KHZ-_D2oQ_BJ6BAhSEAU | AJ29: https://www.jeffersonhealth.org/locations/primary-specialty-care-fish-pond-road/department-directory | AK29: https://www.jeffersonhealth.org/locations/primary-specialty-care-fish-pond-road | AL29: 2026-08-06
A30: Jefferson Radiation Oncology – Washington Township | B30: Practice | D30: 900 Medical Center Drive, Suite 100 | E30: Sewell | F30: NJ | G30: 08080 | I30: 39.73864 | J30: -75.06423 | K30: 856-582-3008 | M30: 856-582-3009 | O30: No | P30: 08:30 am - 05:00 pm | Q30: 08:30 am - 05:00 pm | R30: 08:30 am - 05:00 pm | S30: 08:30 am - 05:00 pm | T30: 08:30 am - 05:00 pm | U30: Closed | V30: Closed | X30: Radiation Oncology | AA30: Yes | AB30: Yes | AC30: Yes | AD30: Yes | AE30: No | AF30: No | AG30: Radiation oncology services at the Sidney Kimmel Comprehensive Cancer Center - Washington Township. | AH30: https://maps.app.goo.gl/AfVC3maQZBTstM4g7 | AK30: https://www.jeffersonhealth.org/locations/jefferson-radiation-oncology-at-washington-township | AL30: 2026-01-24
A31: Jefferson Specialty Care – Washington Township | B31: Practice | D31: 400 Medical Center Drive, Suite F | E31: Sewell | F31: NJ | G31: 08080 | I31: 39.737662 | J31: -75.066067 | K31: 1-800-JEFF-NOW | O31: No | P31: 08:00 am - 04:30 pm | Q31: 08:00 am - 04:30 pm | R31: 08:00 am - 04:30 pm | S31: 08:00 am - 04:30 pm | T31: 08:00 am - 04:30 pm | U31: Closed | V31: Closed | X31: Cancer; Breast Care; Cardiology; Heart & Vascular; Breast Surgery | Y31: Breast Cancer; Heart Failure | AA31: Yes | AB31: Yes | AC31: No | AD31: No | AE31: No | AF31: No | AG31: Jefferson Health offers breast surgery and cardiology care in Washington Township, NJ. | AH31: https://www.google.com/maps/place/Jefferson+Specialty+Care+%E2%80%93+Washington+Township/data=!4m2!3m1!1s0x0:0x9f05de5f8d6f551d?sa=X&ved=1t:2428&hl=en&ictx=111 | AJ31: https://www.jeffersonhealth.org/locations/specialty-care-washington-township/department-directory | AK31: https://www.jeffersonhealth.org/locations/specialty-care-washington-township | AL31: 2026-04-15
A32: Jefferson–Solis Mammography – Washington Township | B32: Imaging | C32: A department of Jefferson Washington Township Hospital | D32: 900 Medical Center Drive, Suite 101 | E32: Sewell | F32: NJ | G32: 08080 | I32: 39.789111 | J32: -75.055274 | K32: 856-474-1445 | O32: No | P32: 07:00 am - 06:00 pm | Q32: 07:00 am - 06:00 pm | R32: 07:00 am - 06:00 pm | S32: 07:00 am - 06:00 pm | T32: 07:00 am - 05:00 pm | U32: Closed | V32: Closed | W32: * Sat: Call for Information. | X32: Breast Care; Breast Imaging; Women's Imaging; Imaging & Radiology | Z32: Abnormal Mammogram; Mammogram; Breast Ultrasound; Breast Biopsy | AA32: Yes | AB32: Yes | AC32: No | AD32: Yes | AE32: No | AF32: No | AG32: Jefferson Health has partnered with Solis Mammography, the nation’s leader in screening and diagnostic mammography, to serve as an on-site provider of comprehensive breast imaging services at Jefferson locations throughout the greater Philadelphia and South Jersey area. | AH32: https://maps.app.goo.gl/FEHTcenWXY5XLmPm9 | AI32: https://www.jeffersonhealth.org/locations/washington-township-hospital/getting-here | AK32: https://www.jeffersonhealth.org/locations/solis-mammography-washington-township | AL32: 2026-01-24
A33: Medical Oncology & Infusion Suite - 900 Medical Center Drive | B33: Practice | D33: 900 Medical Center Drive, Suite 200 | E33: Sewell | F33: NJ | G33: 08080 | I33: 39.738613 | J33: -75.066862 | K33: 856-557-7900 | M33: 856-589-3989 | O33: No | P33: 08:30 am - 05:00 pm | Q33: 08:30 am - 05:00 pm | R33: 08:30 am - 05:00 pm | S33: 08:30 am - 05:00 pm | T33: 08:30 am - 05:00 pm | U33: Closed | V33: Closed | X33: Medical Oncology; Hematology; Brain Tumor Care | AA33: Yes | AB33: Yes | AC33: Yes | AD33: Yes | AE33: No | AF33: No | AG33: Medical oncology services at Sidney Kimmel Comprehensive Cancer Center - Washington Township. | AH33: https://www.google.com/maps/place/900+Medical+Center+Dr,+Blackwood,+NJ+08012/@39.7386127,-75.0668625,17z/data=!3m1!4b1!4m5!3m4!1s0x89c6d6a90e6333a5:0x5acc727456308c35!8m2!3d39.7386127!4d-75.0646738 | AK33: https://www.jeffersonhealth.org/locations/medical-oncology-infusion-suite-900-medical-center-drive | AL33: 2026-01-24
A34: Neurosciences Center Washington Township | B34: Practice | D34: 445 Hurffville Cross Keys Road, Suite B16 | E34: Sewell | F34: NJ | G34: 08080 | I34: 39.735539 | J34: -75.067366 | K34: 856-352-6660 | M34: 856-269-4258 | O34: No | P34: 08:00 am - 05:00 pm | Q34: 08:00 am - 05:00 pm | R34: 08:00 am - 05:00 pm | S34: 08:00 am - 05:00 pm | T34: 08:00 am - 05:00 pm | U34: Closed | V34: Closed | X34: Neuroscience; Neurology | AA34: No | AB34: No | AC34: No | AD34: No | AE34: No | AF34: Yes | AG34: Neuroscience services in Washington Township, NJ. | AH34: https://www.google.com/maps/place/Parking+lot,+445+Hurffville+-+Cross+Keys+Rd+B16,+Sewell,+NJ+08080/data=!4m2!3m1!1s0x89c6d6af56baaaab:0x5e65d2451ebaccf?sa=X&ved=2ahUKEwjDmr7hsd7zAhUrhOAKHS_6Dh4Q8gF6BAgSEAE | AK34: https://www.jeffersonhealth.org/locations/neurosciences-center-washington-township | AL34: 2026-04-28
A35: Point Plaza - Jefferson Gastroenterology | B35: Practice | D35: 565 Egg Harbor Road | E35: Sewell | F35: NJ | G35: 08080 | I35: 39.735304 | J35: -75.06434 | K35: 844-542-2273 | M35: 856-256-1188 | O35: No | P35: 08:00 am - 05:00 pm | Q35: 08:00 am - 05:00 pm | R35: 08:00 am - 05:00 pm | S35: 08:00 am - 05:00 pm | T35: 08:00 am - 05:00 pm | U35: Closed | V35: Closed | X35: Primary Care; Gastroenterology & Hepatology | AA35: No | AB35: No | AC35: No | AD35: No | AE35: No | AF35: Yes | AG35: Primary and specialty care services in Sewell, NJ. | AH35: https://www.google.com/maps/place/Jefferson+Health+Washington+Township+Care+Now/@39.7345942,-75.0663995,17z/data=!3m1!4b1!4m5!3m4!1s0x89c6d6a7c889d3e7:0x98d78d4eb6fe9ca1!8m2!3d39.7346179!4d-75.0642296 | AK35: https://www.jeffersonhealth.org/locations/point-plaza-primary-care | AL35: 2026-01-24
A36: Sewell Primary Care | B36: Practice | D36: 485 Hurffville Cross Keys Road | E36: Sewell | F36: NJ | G36: 08080 | I36: 39.73913 | J36: -75.07323 | K36: 856-557-5555 | M36: 856-218-8192 | O36: No | P36: 08:00 am - 05:00 pm | Q36: 08:00 am - 07:30 pm | R36: 08:00 am - 05:00 pm | S36: 08:00 am - 05:00 pm | T36: 08:00 am - 05:00 pm | U36: Closed | V36: Closed | X36: Psychiatry & Human Behavior; Primary Care; Nutrition | AA36: No | AB36: No | AC36: No | AD36: No | AE36: No | AF36: Yes | AG36: Primary care, behavioral health, and nutrition services in Sewell, NJ. | AH36: https://www.google.com/maps/place/Jefferson+Health+Sewell+Obstetrics+%26+Gynecology/@39.7390546,-75.0759425,17z/data=!3m1!4b1!4m5!3m4!1s0x89c6d4084c044083:0xbbf79d5ade0f6cb!8m2!3d39.7389967!4d-75.073809 | AK36: https://www.jeffersonhealth.org/locations/sewell-primary-care | AL36: 2026-02-27
A37: Sidney Kimmel Comprehensive Cancer Center — Washington Township | B37: Imaging; Outpatient Medical Center | D37: 900 Medical Center Drive | E37: Sewell | F37: NJ | G37: 08080 | I37: 39.738524 | J37: -75.064677 | K37: 856-218-5324 | M37: 856-218-5327 | O37: No | P37: 08:30 am - 05:00 pm | Q37: 08:30 am - 05:00 pm | R37: 08:30 am - 05:00 pm | S37: 08:30 am - 05:00 pm | T37: 08:30 am - 05:00 pm | U37: Closed | V37: Closed | X37: Radiation Oncology; Medical Oncology; Nutrition; Neurosurgery; Breast Medical Oncology; Lung Cancer, Screening, and Nodules; Cardiothoracic Surgery; Imaging & Radiology; Respiratory & Pulmonary Medicine; Sleep Medicine; Cancer; Senior Adult Oncology Center; Breast Care; Outpatient Imaging | Y37: Throat Cancer; Ovarian Cancer; Parathyroid Cancer | AA37: Yes | AB37: Yes | AC37: Yes | AD37: Yes | AE37: No | AF37: No | AG37: Comprehensive cancer services in Washington Township, NJ. | AH37: https://www.google.com/maps/place/Sidney+Kimmel+Cancer+Center+-+Washington+Township/@39.7385238,-75.0668656,17z/data=!3m1!4b1!4m5!3m4!1s0x89c6d6a90d701b4d:0xb264e85f4f581ea3!8m2!3d39.738425!4d-75.064889 | AJ37: https://www.jeffersonhealth.org/locations/sidney-kimmel-cancer-center-washington-township/department-directory | AK37: https://www.jeffersonhealth.org/locations/sidney-kimmel-cancer-center-washington-township | AL37: 2026-03-25
A38: Surgery Center - Washington Township | B38: Surgical Center | D38: 540 Egg Harbor Road | E38: Sewell | F38: NJ | G38: 08080 | I38: 39.948189 | J38: -75.002697 | K38: 856-218-4900 | M38: 856-256-1276 | O38: No | P38: 06:00 am - 04:30 pm | Q38: 06:00 am - 04:30 pm | R38: 06:00 am - 04:30 pm | S38: 06:00 am - 04:30 pm | T38: 06:00 am - 04:30 pm | U38: Closed | V38: Closed | X38: General Surgery; Surgery; Gastroenterology & Hepatology | AA38: Yes | AB38: Yes | AC38: No | AD38: No | AE38: No | AF38: No | AG38: The Surgery team at Jefferson Surgery Center - Washington Township offers expertise you can trust throughout the greater South Jersey area. | AH38: https://www.google.com/maps/dir//washington+township+surgical+center/data=!4m6!4m5!1m1!4e2!1m2!1m1!1s0x89c6d6a8ff2ae6f3:0x9dc4dcd0d1358f4a?sa=X&ved=2ahUKEwjcp--V1J75AhXWFFkFHf0oDyYQ9Rd6BAgOEAU | AK38: https://www.jeffersonhealth.org/locations/surgery-center-washington-township | AL38: 2026-01-24
A39: Jefferson Moss-Magee Rehabilitation – Stratford | B39: Outpatient Rehabilitation | D39: 18 Laurel Rd | E39: Stratford | F39: NJ | G39: 08084 | I39: 39.824483 | J39: -75.012932 | K39: 856-346-7842 | M39: 856-346-6013 | O39: No | X39: Rehabilitation Medicine; Outpatient Rehabilitation; Physical Therapy; Occupational Therapy; Speech Therapy Program; Brain Injury Rehabilitation | Y39: Pelvic Floor Disorder; Lymphedema; Concussion & Head Injuries | Z39: Physical Therapy; Occupational Therapy; Speech Therapy; Pelvic Floor Therapy | AA39: No | AB39: No | AC39: No | AD39: No | AE39: No | AF39: No | AG39: Jefferson Moss-Magee Rehabilitation – Stratford is the largest provider of Physical Medicine and Rehabilitation in the New Jersey region. | AH39: https://www.google.com/maps/place/18+Laurel+Rd,+Stratford,+NJ+08084/@39.8244827,-75.0129319,17z/data=!3m1!4b1!4m6!3m5!1s0x89c6cd793c62866b:0xf10697feea62a4c5!8m2!3d39.8244786!4d-75.010357!16s%2Fg%2F11bw42j31h?entry=ttu | AK39: https://www.jeffersonhealth.org/locations/moss-magee-rehabilitation-stratford | AL39: 2026-07-07
A40: Jefferson Stratford Hospital | B40: Hospital; Imaging | C40: Hospital | D40: 18 East Laurel Road | E40: Stratford | F40: NJ | G40: 08084 | I40: 39.828168 | J40: -75.008266 | K40: 856-346-6000 | L40: Emergency Department: 856-346-7816 | O40: Yes | P40: Open 24 hours | Q40: Open 24 hours | R40: Open 24 hours | S40: Open 24 hours | T40: Open 24 hours | U40: Open 24 hours | V40: Open 24 hours | X40: Neurology; Balance & Hearing; Psychiatry & Human Behavior; Imaging & Radiology; Nutrition; Stroke; Acute Care For Elders Unit; Pelvic Health; Emergency Medicine; Minimally Invasive & Robotic Surgery; Interventional Radiology; Fibroid Care; Hospital Medicine; Hospice & Palliative Care; Outpatient Imaging | Y40: Lymphedema | Z40: Kidney Dialysis | AA40: Yes | AB40: Yes | AC40: No | AD40: Yes | AE40: No | AF40: No | AG40: Expert healthcare, close to home. | AH40: https://www.google.com/maps/place/18+E+Laurel+Rd,+Stratford,+NJ+08084/data=!4m2!3m1!1s0x89c6cd7a0038b1a5:0xfa79a1ef90d1a29a?sa=X&ved=2ahUKEwjSu6mkpPv3AhXpjYkEHZ8CAYsQ8gF6BAgKEAE | AI40: https://www.jeffersonhealth.org/locations/stratford-hospital/getting-here | AJ40: https://www.jeffersonhealth.org/locations/stratford-hospital/department-directory | AK40: https://www.jeffersonhealth.org/locations/stratford-hospital | AL40: 2026-08-28
...

Sheet LVHN
A1: Name | B1: Location Types | C1: Located At | D1: Part Of (Institute) | E1: Street Address | F1: Address Line 1 | G1: Address Line 2 | H1: City | I1: State | J1: ZIP | K1: Latitude | L1: Longitude | M1: Phone | N1: Fax | O1: Hours Note | P1: Monday Hours | Q1: Tuesday Hours | R1: Wednesday Hours | S1: Thursday Hours | T1: Friday Hours | U1: Saturday Hours | V1: Sunday Hours | W1: Other Hours | X1: Hours Text | Y1: Services | Z1: Description | AA1: Alert | AB1: Location URL | AC1: Node ID | AD1: Note
A2: Community Health & Wellness Center | B2: Community Clinics | C2: Lehigh Valley Hospital–17th Street | K2: 40.6 | L2: -75.47 | M2: 610-969-2800 | P2: 8:00-17:00 | Q2: 8:00-17:00 | R2: 8:00-17:00 | S2: 8:00-17:00 | T2: 8:00-17:00 | U2: Closed | V2: Closed | Z2: VHP Mark J. Young Community Health and Wellness Center services include: Health classes in English and Spanish Diabetes self-management education Education and support for people with chronic health conditions and caregivers Medication management Help with weight management Classes on exercise and healthy eating High-risk breast program Well-woman exams (free for uninsured women) We are easily accessible by public transportation. Feel free to bring family members with you. They can learn how to be healthy and prevent illness, too. | AA2: Services Temporarily Relocated to VHP Lehigh Valley Physicians Practice VHP Lehigh Valley Physicians Practice | AB2: https://www.lvhn.org/locations/community-health-wellness-center | AC2: 54583
A3: VHP Center for Women's Medicine-Fairgrounds | B3: Physician Practices | E3: 400 N 17th St., Suite 204 | F3: 400 N 17th St. | G3: Suite 204 | H3: Allentown | J3: 18104-5052 | K3: 40.602157 | L3: -75.495196 | M3: (610) 969-3630 | N3: (610) 433-0949 | O3: Hours vary by service | Y3: Adolescent Gynecology; Prenatal Care | Z3: Learn more about VHP Center for Women's Medicine-Fairgrounds on ValleyHealthPartners.org | AB3: https://www.lvhn.org/locations/vhp-center-womens-medicine-fairgrounds | AC3: 118240
A4: North American Partners In Anesthesia | E4: 68 S Service Road, Suite 350 | F4: 68 S Service Road | G4: Suite 350 | H4: Melville | I4: NY | J4: 11747-2354 | K4: 40.781462 | L4: -73.438495 | M4: (516) 945-3000 | N4: (570) 420-2479 | O4: Hours vary by service | AB4: https://www.lvhn.org/locations/north-american-partners-anesthesia | AC4: 68440
A5: AMC Medical Associates | B5: Physician Practices | E5: 798 Hausman Road, Suite 270 | F5: 798 Hausman Road | G5: Suite 270 | H5: Allentown | I5: PA | J5: 18104-9103 | K5: 40.592883 | L5: -75.563574 | M5: (610) 432-6862 | N5: (610) 432-9705 | O5: General Facility Hours | P5: 8:00 am - 5:00 pm | Q5: 8:00 am - 5:00 pm | R5: 8:00 am - 5:00 pm | S5: 8:00 am - 5:00 pm | T5: 8:00 am - 5:00 pm | U5: Closed | V5: Closed | Y5: Primary Care | AB5: https://www.lvhn.org/locations/amc-medical-associates | AC5: 64633
A6: Advanced Dermatology Associates, Ltd | B6: Physician Practices | E6: 1259 S Cedar Crest Blvd, Suite 100 | F6: 1259 S Cedar Crest Blvd | G6: Suite 100 | H6: Allentown | I6: PA | J6: 18103-6206 | K6: 40.564533 | L6: -75.517025 | M6: (610) 437-4134 | N6: (434) 825-9193 | O6: General Facility Hours | P6: 9:00 am - 5:00 pm | Q6: 8:00 am - 4:00 pm | R6: 1:00 pm - 4:00 pm | S6: Closed | T6: Closed | U6: Closed | V6: Closed | Y6: Pediatric Dermatology | AB6: https://www.lvhn.org/locations/advanced-dermatology-associates-ltd | AC6: 64449
A7: Audiology at Lehigh Valley Hospital–Cedar Crest | B7: Testing and Imaging Centers | C7: Lehigh Valley Hospital–Cedar Crest | E7: 1200 S. Cedar Crest Blvd., Pool Family Pavilion, 1st Floor | F7: 1200 S. Cedar Crest Blvd. | G7: Pool Family Pavilion, 1st Floor | H7: Allentown | I7: PA | J7: 18103 | K7: 40.56671 | L7: -75.523755 | O7: Hours vary by service | Y7: Rehabilitation Services | Z7: Hours vary. Call 888-402-LVHN to schedule an appointment. | AB7: https://www.lvhn.org/locations/audiology-lehigh-valley-hospital-cedar-crest | AC7: 65484
A8: Bognet Medical Associates, PC | B8: Physician Practices | E8: 1275 S Cedar Crest Blvd, Suite 5 | F8: 1275 S Cedar Crest Blvd | G8: Suite 5 | H8: Allentown | I8: PA | J8: 18103-6207 | K8: 40.562861 | L8: -75.517079 | M8: (610) 821-2820 | N8: (610) 821-2859 | O8: Hours vary by service | Y8: Adolescent Gynecology; Primary Care; Smoking Cessation Counseling; Sports Medicine | AB8: https://www.lvhn.org/locations/bognet-medical-associates-pc | AC8: 64472
A9: Breast Health Services at 1405 N. Cedar Crest | B9: Specialty Care Facilities; Testing and Imaging Centers | E9: 1405 N Cedar Crest Blvd, Suite 200 | F9: 1405 N Cedar Crest Blvd | G9: Suite 200 | H9: Allentown | I9: PA | J9: 18104 | K9: 40.612017 | L9: -75.529353 | M9: 610-402- 8378 | O9: General Facility Hours | P9: 7:00 am - 3:30 pm | Q9: 7:00 am - 3:30 pm | R9: 7:00 am - 3:30 pm | S9: 7:00 am - 3:30 pm | T9: 7:00 am - 3:30 pm | U9: Closed | V9: Closed | X9: Walk-ins welcomed. | Y9: Breast Health Services; Mammogram | Z9: Our Breast Health Services team provides you with convenient access to advanced breast cancer screening technologies, including: Screening 3D mammograms (tomosynthesis) Our dedicated care team includes mammography- and ultrasound-certified technologists, board-certified radiologists and oncology-certified nurses who will support you throughout every stage of your care journey. The American College of Radiology™ has recognized LVHN as an ACR Designated Comprehensive Breast Imaging Center . This designation means we deliver safe and accurate breast cancer screenings. Our additional accreditations and recognitions from quality programs include: National Accreditation Program for Breast Centers through the American College of Surgeons National Quality Measures for Breast Centers® through the National Consortium of Breast Centers™ | AB9: https://www.lvhn.org/locations/breast-health-services-1405-n-cedar-crest | AC9: 99217
A10: Breast Health Services at Lehigh Valley Hospital–17th Street | B10: Testing and Imaging Centers | C10: Lehigh Valley Hospital–17th Street | E10: 1627 W. Chew St. | F10: 1627 W. Chew St. | H10: Allentown | I10: PA | J10: 18102 | K10: 40.601282 | L10: -75.494303 | M10: 610-402-2791 | O10: General Facility Hours | P10: 7:00 am - 5:00 pm | Q10: 7:00 am - 5:00 pm | R10: 7:00 am - 5:00 pm | S10: 7:00 am - 5:00 pm | T10: 7:00 am - 4:00 pm | U10: Closed | V10: Closed | Y10: Breast Health Services; Mammogram | Z10: We provide advanced breast imaging for breast cancer screening and diagnosis. Breast Health Services offers: Screening mammograms Tomosynthesis (also called 3D mammograms) Diagnostic mammograms for new clinical breast problems Follow-up imaging after an abnormal mammogram Breast ultrasounds Breast biopsy procedures, including ultrasound-guided core biopsy and stereotactic core biopsy Breast Health Services is an American College of Radiology Accredited Center of Excellence. We also maintain accreditation in other quality programs, including: National Accreditation Program for Breast Centers (NAPBC) through the American College of Surgeons National Quality Measure of Breast Centers through the National Consortium of Breast Centers | AB10: https://www.lvhn.org/locations/breast-health-services-lehigh-valley-hospital-17th-street | AC10: 54574
A11: Breast Health Services at Lehigh Valley Hospital–Cedar Crest | B11: Testing and Imaging Centers | C11: Lehigh Valley Hospital–Cedar Crest | E11: 1240 S Cedar Crest Blvd, Suite 203 | F11: 1240 S Cedar Crest Blvd | G11: Suite 203 | H11: Allentown | I11: PA | J11: 18103-6218 | K11: 40.566494 | L11: -75.521491 | M11: 610-402-0690 | O11: General Facility Hours | P11: 7:00 am - 6:00 pm | Q11: 7:00 am - 6:00 pm | R11: 7:00 am - 6:00 pm | S11: 7:00 am - 6:00 pm | T11: 7:00 am - 4:00 pm | U11: 7:00 am - 3:30 pm (1st and 3rd Saturdays only) | V11: Closed | Y11: Breast Health Services; Breast Magnetic Resonance Imaging (MRI); Mammogram; Oncology | Z11: Our services Breast Health Services is an ACR Accredited Center of Excellence, maintaining accreditation in many quality programs , including: NAPBC (National Accreditation Program for Breast Centers through the American College of Surgeons) NQMBC (National Quality Measure of Breast Centers through the National Consortium of Breast Centers). Our dedicated, professional staff includes mammography-certified technologists, board-certified dedicated radiologists, and oncology-certified nurses. We provide advanced breast imaging for breast cancer screening and diagnosis. Breast Health Services offers: Screening mammograms Automated Breast Ultrasound (ABUS) Tomosynthesis , or 3D mammography Diagnostic mammograms for new clinical breast problems Follow up from an abnormal mammogram Breast ultrasounds Breast biopsy procedures via either ultrasound-guided core biopsy or stereotactic core biopsy | AB11: https://www.lvhn.org/locations/breast-health-services-lehigh-valley-hospital-cedar-crest | AC11: 54571
A12: Breidegam Family Children’s ER at Lehigh Valley Hospital-Cedar Crest | B12: Children's Hospital; Emergency Rooms | E12: 1200 S Cedar Crest Blvd, PO Box 689 | F12: 1200 S Cedar Crest Blvd | G12: PO Box 689 | H12: Allentown | I12: PA | J12: 18103-6202 | K12: 40.566346 | L12: -75.523839 | M12: (610) 402-9750 | N12: (610) 402-9763 | O12: Open 24 hours | P12: Open 24 hours | Q12: Open 24 hours | R12: Open 24 hours | S12: Open 24 hours | T12: Open 24 hours | U12: Open 24 hours | V12: Open 24 hours | Y12: Children\u2019s ER; Pediatric Trauma Care | Z12: Lehigh Valley Reilly Children’s Hospital has the region’s most experienced 24/7 emergency room dedicated to children. Located at Lehigh Valley Hospital–Cedar Crest and built just for kids, the 27-bed Breidegam Family Children’s ER is staffed by board-certified pediatric emergency medicine physicians who skillfully and compassionately care for ill and injured kids. Serving families from Allentown, Emmaus and Lehigh County to the Lehigh Valley and beyond, our Children’s ER is one of the most trusted emergency rooms for pediatric care. Highly trained staff provide emergency care for kids The Breidegam Family Children’s ER is run by board-certified pediatric emergency physicians. They are supported by: Advanced practice clinicians who are experienced in caring for kids A nursing team specially trained in pediatric emergency nursing Pediatric pharmacists for accurate medication dosing Child-life specialists who make the hospital experience less stressful for children Pediatric respiratory t | AB12: https://www.lvhn.org/locations/breidegam-family-childrens-er-lehigh-valley-hospital-cedar-crest | AC12: 78696
A13: Burn Recovery Center | B13: Specialty Care Facilities | C13: Lehigh Valley Hospital–Cedar Crest | D13: Lehigh Valley Institute for Surgical Excellence | E13: 1200 S. Cedar Crest Blvd, 3rd Floor Kasych Pavilion | F13: 1200 S. Cedar Crest Blvd | G13: 3rd Floor Kasych Pavilion | H13: Allentown | I13: PA | J13: 18103-6202 | K13: 40.566346 | L13: -75.523839 | M13: (610) 402-8355 | N13: (610) 402-2877 | O13: General Facility Hours | P13: 8:00 am - 5:00 pm | Q13: 8:00 am - 5:00 pm | R13: 8:00 am - 5:00 pm | S13: 8:00 am - 5:00 pm | T13: 8:00 am - 5:00 pm | U13: Closed | V13: Closed | Y13: Adolescent Gynecology; Burn Treatment; Pediatric Trauma Care; Primary Care; Smoking Cessation Counseling; Sports Medicine | Z13: In addition to providing leading-edge burn care and rehabilitation services, we provide state-of-the-art scar management, including: Evaluation for reconstructive or plastic surgery Scar massage Splint fabrication Pressure garment therapy Laser and light therapy Cosmetic consultations Permanent makeup to hide scars Therapy to help you cope with emotional challenges LVHN’s Burn Recovery Center is the only one in northeastern Pennsylvania certified by the American Burn Association and the American College of Surgeons to care for adults and children. | AB13: https://www.lvhn.org/locations/burn-recovery-center | AC13: 54575
A14: Cancer Support Services-Cedar Crest | B14: Specialty Care Facilities | C14: Lehigh Valley Hospital–Cedar Crest | D14: Lehigh Valley Topper Cancer Institute | E14: 1240 S Cedar Crest Blvd, Allentown, PA 18103, Suite 310 | F14: 1240 S Cedar Crest Blvd, Allentown, PA 18103 | G14: Suite 310 | H14: Allentown | I14: PA | J14: 18103-6369 | K14: 40.566494 | L14: -75.521491 | M14: 610-402-9546 | N14: 610-402-9576 | O14: Hours vary by service | Y14: Young Adult SurvivorPLACE | Z14: A physician or nurse practitioner will perform an exam and routine surveillance screening. Our team of oncology professionals also can provide recommendations for lasting effects related to cancer or its treatment. The Young Adult Survivor PLACE team also includes a rehabilitation specialist, dietitian, social worker, and a nurse navigator. | AB14: https://www.lvhn.org/locations/cancer-support-services-cedar-crest | AC14: 94898
A15: Cardiac Diagnostic Center at Lehigh Valley Hospital–Cedar Crest | B15: Testing and Imaging Centers | C15: Lehigh Valley Hospital–Cedar Crest | D15: Lehigh Valley Heart and Vascular Institute | E15: 1250 S. Cedar Crest Blvd., Suite 305 | F15: 1250 S. Cedar Crest Blvd. | G15: Suite 305 | H15: Allentown | I15: PA | J15: 18103 | K15: 40.566568 | L15: -75.519745 | O15: Hours vary by service | X15: Hours vary by test | Y15: Echocardiogram; Exercise Treadmill Stress Test; Heart Imaging; Holter Monitor; Nuclear Stress Test; Stress Echocardiogram; Vascular Studies | Z15: The Cardiac Diagnostic Center at Lehigh Valley Hospital–Cedar Crest is also known as the Heart Station. Hours by test are listed below: Echocardiogram Mon.-Fri. 7:30 a.m. to 5 p.m. Exercise treadmill stress test Mon.-Fri. 7:30 a.m. to 3 p.m. Holter monitor Mon.-Fri. 7:30 a.m. to 3 p.m. Nuclear stress test Mon.-Fri. 7:30 a.m. to 3 p.m. Stress echocardiogram Mon.-Fri. 7:30 a.m. to 3 p.m. Vascular studies Tues. and Fri. 8 a.m. to 4:30 p.m. A service of Lehigh Valley Hospital. | AB15: https://www.lvhn.org/locations/cardiac-diagnostic-center-lehigh-valley-hospital-cedar-crest | AC15: 65411
A16: Cardiac Rehabilitation–1250 Cedar Crest | B16: Rehabilitation Locations | C16: Lehigh Valley Hospital–Cedar Crest | D16: Lehigh Valley Heart and Vascular Institute | E16: 1250 S. Cedar Crest Blvd., Suite 112 | F16: 1250 S. Cedar Crest Blvd. | G16: Suite 112 | H16: Allentown | I16: PA | J16: 18103 | K16: 40.566568 | L16: -75.519745 | M16: 610-402-5915 | O16: General Facility Hours | P16: 7:30 am - 5:30 pm | Q16: 7:30 am - 4:30 pm | R16: 7:30 am - 5:30 pm | S16: 7:30 am - 4:30 pm | T16: 7:30 am - 5:30 pm | U16: Closed | V16: Closed | Y16: Cardiac Rehabilitation; Pulmonary Rehabilitation | Z16: A service of Lehigh Valley Hospital. | AB16: https://www.lvhn.org/locations/cardiac-rehabilitation-1250-cedar-crest | AC16: 80879
A17: Center for Advanced Health Care | B17: Specialty Care Facilities | C17: Lehigh Valley Hospital–Cedar Crest | E17: 1250 S. Cedar Crest Blvd. | F17: 1250 S. Cedar Crest Blvd. | H17: Allentown | I17: PA | J17: 18103-6224 | K17: 40.566568 | L17: -75.519745 | O17: Hours vary by service | Z17: The Center for Advanced Health Care on the campus of Lehigh Valley Hospital–Cedar Crest is home to the following physician practices and services: First Floor Imaging services (CT) LVPG Orthopedics and Sports Medicine Second Floor LVPG Infectious Diseases–1250 Cedar Crest LVPG Pulmonary and Critical Care Medicine–1250 Cedar Crest LVPG Transplant Surgery–1250 Cedar Crest LVPG Urology–1250 Cedar Crest Third Floor LVPG Cardiology–1250 Cedar Crest Cardiac Diagnostic Center LVPG Cardiac and Thoracic Surgery–1250 Cedar Crest Fourth Floor Neuroscience Center LVPG Neurology–1250 Cedar Crest Neuropsychiatry services Valet parking is available Monday – Friday: 7 a.m. – 5 p.m. (last vehicle accepted at 4 p.m.). A service of Lehigh Valley Hospital. | AB17: https://www.lvhn.org/locations/center-advanced-health-care | AC17: 54624
A18: Center for Orthopedic Medicine–Tilghman | B18: Specialty Care Facilities | C18: Lehigh Valley Health Network–Tilghman | D18: Lehigh Valley Orthopedic Institute | E18: 4815 Tilghman Street | F18: 4815 Tilghman Street | H18: Allentown | I18: PA | J18: 18104 | K18: 40.590734 | L18: -75.562906 | M18: 610-402-3903 | O18: Hours vary by service | Y18: Orthopedics; Robotic-Assisted Knee Replacement; Sports Medicine; Surgery | AB18: https://www.lvhn.org/locations/center-orthopedic-medicine-tilghman | AC18: 69477
A19: Children's Hospital of Philadelphia-Cardiac Center Allentown | B19: Children's Hospital; Physician Practices | E19: 1605 N Cedar Crest Blvd, Suites 117 & 119 | F19: 1605 N Cedar Crest Blvd | G19: Suites 117 & 119 | H19: Allentown | I19: PA | J19: 18104-2351 | K19: 40.614893 | L19: -75.531593 | M19: (610) 437-6687 | N19: (610) 437-5232 | O19: Hours vary by service | AB19: https://www.lvhn.org/locations/childrens-hospital-philadelphia-cardiac-center-allentown | AC19: 67441
